<?xml version="1.0" encoding="utf-8"?>
<!-- =================================================================================== -->
<!-- |    This document was autogenerated by xacro from minimal_robot.urdf.xacro       | -->
<!-- |    EDITING THIS FILE BY HAND IS NOT RECOMMENDED                                 | -->
<!-- =================================================================================== -->
<robot name="MinimalRobot">
  <!--  <xacro:include filename="$(find ros2_control_demo_robot)/description/demo_2dof/robot_2dof.urdf.xacro" />
  <xacro:include filename="$(find ros2_control_demo_robot)/description/demo_2dof/robot_2dof.gazebo.xacro" />
  <xacro:include filename="$(find ros2_control_demo_robot)/description/demo_2dof/robot_2dof.ros2_control.xacro" />-->
  <!-- Used for fixing robot -->
  <link name="world"/>
  <gazebo reference="world">
    <static>true</static>
  </gazebo>
  <joint name="base_joint" type="fixed">
    <origin rpy="0 0 0" xyz="0 0 0"/>
    <parent link="world"/>
    <child link="base_link"/>
  </joint>
  <link name="base_link">
    <inertial>
      <mass value="0.01"/>
      <origin xyz="0 0 0"/>
      <inertia ixx="0.001" ixy="0.0" ixz="0.0" iyy="0.001" iyz="0.0" izz="0.001"/>
    </inertial>
    <visual>
      <origin rpy="0 0 0" xyz="0 0 0"/>
      <geometry>
        <cylinder length="0.2" radius="0.1"/>
      </geometry>
      <material name="DarkGrey">
        <color rgba="0.4 0.4 0.4 1.0"/>
      </material>
    </visual>
    <collision>
      <origin rpy="0 0 0" xyz="0 0 0"/>
      <geometry>
        <cylinder length="1" radius="0.1"/>
      </geometry>
    </collision>
  </link>
  <joint name="joint1" type="revolute">
    <origin rpy="-1.57079632679 0 0" xyz="0 0 0.2"/>
    <parent link="base_link"/>
    <child link="link1"/>
    <limit effort="0.1" lower="-3.14159265359" upper="3.14159265359" velocity="0.2"/>
  </joint>
  <link name="link1">
    <inertial>
      <mass value="0.01"/>
      <origin xyz="0 0 0"/>
      <inertia ixx="0.001" ixy="0.0" ixz="0.0" iyy="0.001" iyz="0.0" izz="0.001"/>
    </inertial>
    <visual>
      <origin rpy="0 0 0" xyz="0 0 0"/>
      <geometry>
        <cylinder length="1" radius="0.1"/>
      </geometry>
      <material name="DarkGrey">
        <color rgba="0.4 0.4 0.4 1.0"/>
      </material>
    </visual>
    <collision>
      <origin rpy="0 0 0" xyz="0 0 0"/>
      <geometry>
        <cylinder length="1" radius="0.1"/>
      </geometry>
    </collision>
  </link>
  <joint name="joint2" type="revolute">
    <origin rpy="1.57079632679 0 0" xyz="0 0 0.9"/>
    <parent link="link1"/>
    <child link="link2"/>
    <limit effort="0.1" lower="-3.14159265359" upper="3.14159265359" velocity="0.2"/>
  </joint>
  <link name="link2">
    <inertial>
      <mass value="0.01"/>
      <origin xyz="0 0 0"/>
      <inertia ixx="0.001" ixy="0.0" ixz="0.0" iyy="0.001" iyz="0.0" izz="0.001"/>
    </inertial>
    <visual>
      <origin rpy="0 0 0" xyz="0 0 0"/>
      <geometry>
        <cylinder length="1" radius="0.1"/>
      </geometry>
      <material name="DarkGrey">
        <color rgba="0.4 0.4 0.4 1.0"/>
      </material>
    </visual>
    <collision>
      <origin rpy="0 0 0" xyz="0 0 0"/>
      <geometry>
        <cylinder length="1" radius="0.1"/>
      </geometry>
    </collision>
  </link>
  <joint name="tool_joint" type="fixed">
    <origin rpy="0 0 0" xyz="0 0 1"/>
    <parent link="link2"/>
    <child link="tool_link"/>
  </joint>
  <link name="tool_link">
    </link>
  <gazebo reference="base_link">
    <material>Gazebo/Gray</material>
  </gazebo>
  <gazebo reference="link1">
    <material>Gazebo/Gray</material>
  </gazebo>
  <gazebo reference="link2">
    <material>Gazebo/Gray</material>
  </gazebo>
  <gazebo>
    <plugin filename="libgazebo_ros_control.so" name="gazebo_ros_control">
      </plugin>
  </gazebo>
  <ros2_control name="MinimalRobot">
    <hardware>
      <classType>ros2_control_demo_hardware/DemoRobotHardwareMinimal</classType>
      <param name="write_for_sec">2</param>
      <param name="read_for_sec">2</param>
    </hardware>
    <actuator name="joint1_position_actuator">
      <classType>ros2_control_components/PositionActuator</classType>
      <joint name="joint1">
        <interfaceName>position</interfaceName>
      </joint>
      <param name="can_read">True</param>
      <param name="min_values">-1</param>
      <param name="max_values">1</param>
    </actuator>
    <actuator name="joint2_position_actuator">
      <classType>ros2_control_components/PositionActuator</classType>
      <joint name="joint2">
        <interfaceName>position</interfaceName>
      </joint>
      <param name="can_read">True</param>
      <param name="min_values">-1</param>
      <param name="max_values">1</param>
    </actuator>
  </ros2_control>
  <transmission name="tran1">
    <type>transmission_interface/SimpleTransmission</type>
    <joint name="joint1">
      <hardwareInterface>PositionJointInterface</hardwareInterface>
    </joint>
    <actuator name="motor1">
      <mechanicalReduction>1</mechanicalReduction>
    </actuator>
  </transmission>
  <transmission name="tran2">
    <type>transmission_interface/SimpleTransmission</type>
    <joint name="joint2">
      <hardwareInterface>VelocityJointInterface</hardwareInterface>
    </joint>
    <actuator name="motor2">
      <mechanicalReduction>1</mechanicalReduction>
    </actuator>
  </transmission>
</robot>

